/storage/brno2/home/ahajek/miniconda3/envs/BARTtrainH100/lib/python3.8/site-packages/torch/utils/data/datapipes/utils/common.py:137: UserWarning: Local function is not supported by pickle, please use regular python function or functools.partial instead.
  warnings.warn(
0it [00:00, ?it/s]0it [00:00, ?it/s]
Traceback (most recent call last):
  File "../predict.py", line 194, in <module>
    app()
  File "/storage/brno2/home/ahajek/miniconda3/envs/BARTtrainH100/lib/python3.8/site-packages/typer/main.py", line 328, in __call__
    raise e
  File "/storage/brno2/home/ahajek/miniconda3/envs/BARTtrainH100/lib/python3.8/site-packages/typer/main.py", line 311, in __call__
    return get_command(self)(*args, **kwargs)
  File "/storage/brno2/home/ahajek/miniconda3/envs/BARTtrainH100/lib/python3.8/site-packages/click/core.py", line 1157, in __call__
    return self.main(*args, **kwargs)
  File "/storage/brno2/home/ahajek/miniconda3/envs/BARTtrainH100/lib/python3.8/site-packages/typer/core.py", line 716, in main
    return _main(
  File "/storage/brno2/home/ahajek/miniconda3/envs/BARTtrainH100/lib/python3.8/site-packages/typer/core.py", line 216, in _main
    rv = self.invoke(ctx)
  File "/storage/brno2/home/ahajek/miniconda3/envs/BARTtrainH100/lib/python3.8/site-packages/click/core.py", line 1434, in invoke
    return ctx.invoke(self.callback, **ctx.params)
  File "/storage/brno2/home/ahajek/miniconda3/envs/BARTtrainH100/lib/python3.8/site-packages/click/core.py", line 783, in invoke
    return __callback(*args, **kwargs)
  File "/storage/brno2/home/ahajek/miniconda3/envs/BARTtrainH100/lib/python3.8/site-packages/typer/main.py", line 683, in wrapper
    return callback(**use_params)  # type: ignore
  File "../predict.py", line 147, in main
    for i, batch in tqdm(enumerate(loader)):
  File "/storage/brno2/home/ahajek/miniconda3/envs/BARTtrainH100/lib/python3.8/site-packages/tqdm/std.py", line 1182, in __iter__
    for obj in iterable:
  File "/storage/brno2/home/ahajek/miniconda3/envs/BARTtrainH100/lib/python3.8/site-packages/torch/utils/data/dataloader.py", line 633, in __next__
    data = self._next_data()
  File "/storage/brno2/home/ahajek/miniconda3/envs/BARTtrainH100/lib/python3.8/site-packages/torch/utils/data/dataloader.py", line 1345, in _next_data
    return self._process_data(data)
  File "/storage/brno2/home/ahajek/miniconda3/envs/BARTtrainH100/lib/python3.8/site-packages/torch/utils/data/dataloader.py", line 1371, in _process_data
    data.reraise()
  File "/storage/brno2/home/ahajek/miniconda3/envs/BARTtrainH100/lib/python3.8/site-packages/torch/_utils.py", line 644, in reraise
    raise exception
KeyError: Caught KeyError in DataLoader worker process 0.
Original Traceback (most recent call last):
  File "/storage/brno2/home/ahajek/miniconda3/envs/BARTtrainH100/lib/python3.8/site-packages/torch/utils/data/_utils/worker.py", line 308, in _worker_loop
    data = fetcher.fetch(index)
  File "/storage/brno2/home/ahajek/miniconda3/envs/BARTtrainH100/lib/python3.8/site-packages/torch/utils/data/_utils/fetch.py", line 32, in fetch
    data.append(next(self.dataset_iter))
  File "/storage/brno2/home/ahajek/miniconda3/envs/BARTtrainH100/lib/python3.8/site-packages/torch/utils/data/datapipes/_hook_iterator.py", line 144, in __next__
    return self._get_next()
  File "/storage/brno2/home/ahajek/miniconda3/envs/BARTtrainH100/lib/python3.8/site-packages/torch/utils/data/datapipes/_hook_iterator.py", line 132, in _get_next
    result = next(self.iterator)
  File "/storage/brno2/home/ahajek/miniconda3/envs/BARTtrainH100/lib/python3.8/site-packages/torch/utils/data/datapipes/_hook_iterator.py", line 215, in wrap_next
    result = next_func(*args, **kwargs)
  File "/storage/brno2/home/ahajek/miniconda3/envs/BARTtrainH100/lib/python3.8/site-packages/torch/utils/data/datapipes/datapipe.py", line 369, in __next__
    return next(self._datapipe_iter)
  File "/storage/brno2/home/ahajek/miniconda3/envs/BARTtrainH100/lib/python3.8/site-packages/torch/utils/data/datapipes/_hook_iterator.py", line 173, in wrap_generator
    response = gen.send(None)
  File "/storage/brno2/home/ahajek/miniconda3/envs/BARTtrainH100/lib/python3.8/site-packages/torch/utils/data/datapipes/iter/callable.py", line 123, in __iter__
    yield self._apply_fn(data)
  File "/storage/brno2/home/ahajek/miniconda3/envs/BARTtrainH100/lib/python3.8/site-packages/torch/utils/data/datapipes/iter/callable.py", line 88, in _apply_fn
    return self.fn(data)
  File "/auto/brno2/home/ahajek/Spektro/MassGenie/data_utils.py", line 276, in <lambda>
    datapipe = datapipe.map(lambda d: preprocess_datapoint(d, source_token, preprocess_args))
  File "/auto/brno2/home/ahajek/Spektro/MassGenie/data_utils.py", line 143, in preprocess_datapoint
    do_log_binning=preprocess_args["do_log_binning"],
KeyError: 'do_log_binning\nThis exception is thrown by __iter__ of MapperIterDataPipe()'

